Workbook

Sheet Summary
B1: Operation Uptime — model summary (hypothetical Tesla Giga Berlin maintenance hiring)
B2: Everything on this tab is a live link to the model. Inputs live only on the Assumptions tab (blue on yellow).
B4: Target: signed contracts by 31 Dec | C4: =Funnel!B9 -> 100
B5: Recommended budget | C5: =Budget!C12 -> 122500
B6: …of which planned spend | C6: =Budget!C9 -> 102255.85
B7: …of which reserve (incl. rounding up) | C7: =Budget!C12-Budget!C9 -> 20244.152
B8: Hires the channel plan buys | C8: =Budget!C13 -> 100
B9: ="Hires actually possible (≤ "&Assumptions!$D$9&" assessments/week)" -> Hires actually possible (≤ 55 assessments/week) | C9: =MIN(Budget!C13,Funnel!B26) -> 100
B10: Media cost per hire | C10: =Budget!C14 -> 1022.5585
B11: Qualified applicants to assess | C11: =Funnel!B23 -> 307.97308
B12: Assessment slots available (capacity × weeks) | C12: =Funnel!B22 -> 314.28571
B13: Slot utilisation | C13: =Funnel!B24 -> 0.97991433
B14: Last useful application date (E/M/A) | C14: =Funnel!B19 -> 46350
B15: Last useful application date (Supervisors) | C15: =Funnel!B20 -> 46343
B16: Hardest role (dearest last hire we must buy; reasons on Funnel row 35) | C16: =IF(MAX(Funnel!H30:H33)<=0,"–",INDEX(Funnel!A30:A33,MATCH(MAX(Funnel!H30:H33),Funnel!H30:H33,0))&" (last hire costs €"&TEXT(MAX(Funnel!H30:H33),"#,##0")&")") -> Electricians (last hire costs €2,272)
B17: Most sensitive assumption | C17: =Funnel!D49 -> Qualified → signed (assessment pass rate) ×0.7
B18: Hires with 30% less budget | C18: =Budget!H46 -> 87.057806
B19: Input checks | C19: =IF(((Assumptions!$D$10<0)+(Assumptions!$D$10>1)+(Assumptions!$D$52<0)+(Assumptions!$D$52>1)+(Assumptions!$D$50<0)+(Assumptions!$D$50>1)+(Assumptions!$D$64<0)+(Assumptions!$D$64>1)+(Assumptions!$D$157<0)+(Assumptions!$D$157>1)+(Assumptions!$D$158<0)+(Assumptions!$D$158>1)+(Assumptions!$D$163<0)+(Assumptions!$D$163>1)+(Assumptions!$D$168<0)+(Assumptions!$D$168>1)+(Assumptions!$D$170<0)+(Assumptions!$D$170>1)+(Assumptions!$D$174<0)+(Assumptions!$D$174>1)+(Assumptions!$D$93<0)+(Assumptions!$D$93>1)+(Assumptions!$D$94<0)+(Assumptions!$D$94>1)+(Assumptions!$D$95<0)+(Assumptions!$D$95>1)+(Assumptions!$D$89<0)+(Assumptions!$D$89>1)+(Assumptions!$D$91<0)+(Assumptions!$D$91>1)+(Assumptions!$D$29<0)+(Assumptions!$D$29>1)+(Assumptions!$D$30<0)+(Assumptions!$D$30>1)+(Assumptions!$D$31<0)+(Assumptions!$D$31>1)+(Assumptions!$D$32<0)+(Assumptions!$D$32>1)+(Assumptions!$D$33<0)+(Assumptions!$D$33>1)+(Assumptions!$D$34<0)+(Assumptions!$D$34>1)+(Assumptions!$D$35<0)+(Assumptions!$D$35>1)+(Assumptions!$D$36<0)+(Assumptions!$D$36>1)+(Assumptions!$D$37<0)+(Assumptions!$D$37>1)+(Assumptions!$D$38<0)+(Assumptions!$D$38>1)+(Assumptions!$D$39<0)+(Assumptions!$D$39>1)+(Assumptions!$D$40<0)+(Assumptions!$D$40>1)+(Assumptions!$D$41<0)+(Assumptions!$D$41>1)+(Assumptions!$D$42<0)+(Assumptions!$D$42>1)+(Assumptions!$D$43<0)+(Assumptions!$D$43>1)+(Assumptions!$D$44<0)+(Assumptions!$D$44>1)+(Assumptions!$D$53<0)+(Assumptions!$D$53>1)+(Assumptions!$D$54<0)+(Assumptions!$D$54>1)+(Assumptions!$D$55<0)+(Assumptions!$D$55>1)+(Assumptions!$D$56<0)+(Assumptions!$D$56>1)+(Assumptions!$D$57<0)+(Assumptions!$D$57>1)+(Assumptions!$D$58<0)+(Assumptions!$D$58>1)+(Assumptions!$D$59<0)+(Assumptions!$D$59>1)+(Assumptions!$D$60<0)+(Assumptions!$D$60>1)+(Assumptions!$D$61<0)+(Assumptions!$D$61>1)+(Assumptions!$D$62<0)+(Assumptions!$D$62>1)+(Assumptions!$D$63<0)+(Assumptions!$D$63>1)+(Assumptions!$D$72<0)+(Assumptions!$D$72>1)+(Assumptions!$D$73<0)+(Assumptions!$D$73>1)+(Assumptions!$D$74<0)+(Assumptions!$D$74>1)+(Assumptions!$D$75<0)+(Assumptions!$D$75>1)+(Assumptions!$D$96<0)+(Assumptions!$D$96>1)+(Assumptions!$D$99<0)+(Assumptions!$D$99>1)+(Assumptions!$D$100<0)+(Assumptions!$D$100>1)+(Assumptions!$D$101<0)+(Assumptions!$D$101>1)+(Assumptions!$D$102<0)+(Assumptions!$D$102>1)+(Assumptions!$D$108<0)+(Assumptions!$D$108>1)+(Assumptions!$D$109<0)+(Assumptions!$D$109>1)+(Assumptions!$D$110<0)+(Assumptions!$D$110>1)+(Assumptions!$D$111<0)+(Assumptions!$D$111>1)+(Assumptions!$D$112<0)+(Assumptions!$D$112>1)+(Assumptions!$D$113<0)+(Assumptions!$D$113>1)+(Assumptions!$D$115<0)+(Assumptions!$D$115>1)+(Assumptions!$D$121<0)+(Assumptions!$D$121>1)+(Assumptions!$D$122<0)+(Assumptions!$D$122>1)+(Assumptions!$D$123<0)+(Assumptions!$D$123>1))+((Assumptions!$D$9<0)+(Assumptions!$D$11<0)+(Assumptions!$D$12<0)+(Assumptions!$D$13<0)+(Assumptions!$D$14<0)+(Assumptions!$D$15<0)+(Assumptions!$D$19<0)+(Assumptions!$D$21<0)+(Assumptions!$D$22<0)+(Assumptions!$D$23<0)+(Assumptions!$D$24<0)+(Assumptions!$D$25<0)+(Assumptions!$D$49<0)+(Assumptions!$D$51<0)+(Assumptions!$D$68<0)+(Assumptions!$D$69<0)+(Assumptions!$D$70<0)+(Assumptions!$D$71<0)+(Assumptions!$D$76<0)+(Assumptions!$D$77<0)+(Assumptions!$D$78<0)+(Assumptions!$D$79<0)+(Assumptions!$D$83<0)+(Assumptions!$D$84<0)+(Assumptions!$D$85<0)+(Assumptions!$D$86<0)+(Assumptions!$D$87<0)+(Assumptions!$D$88<0)+(Assumptions!$D$90<0)+(Assumptions!$D$92<0)+(Assumptions!$D$97<0)+(Assumptions!$D$98<0)+(Assumptions!$D$103<0)+(Assumptions!$D$114<0)+(Assumptions!$D$116<0)+(Assumptions!$D$117<0)+(Assumptions!$D$118<0)+(Assumptions!$D$119<0)+(Assumptions!$D$120<0)+(Assumptions!$D$124<0)+(Assumptions!$D$125<0)+(Assumptions!$D$126<0)+(Assumptions!$D$153<0)+(Assumptions!$D$154<0)+(Assumptions!$D$155<0)+(Assumptions!$D$156<0)+(Assumptions!$D$159<0)+(Assumptions!$D$160<0)+(Assumptions!$D$161<0)+(Assumptions!$D$162<0)+(Assumptions!$D$164<0)+(Assumptions!$D$165<0)+(Assumptions!$D$166<0)+(Assumptions!$D$167<0)+(Assumptions!$D$169<0)+(Assumptions!$D$171<0)+(Assumptions!$D$172<0)+(Assumptions!$D$173<0)+(Assumptions!$D$175<0)+(Assumptions!$D$176<0)+(Assumptions!$D$177<0)+(Assumptions!$D$178<0)+(Assumptions!$D$179<0)+(Assumptions!$D$180<0)+(Assumptions!$D$181<0)+(Assumptions!$D$182<0))+((INT(Assumptions!$D$19)<>Assumptions!$D$19)+(INT(Assumptions!$D$21)<>Assumptions!$D$21)+(INT(Assumptions!$D$22)<>Assumptions!$D$22)+(INT(Assumptions!$D$23)<>Assumptions!$D$23)+(INT(Assumptions!$D$24)<>Assumptions!$D$24)+(INT(Assumptions!$D$25)<>Assumptions!$D$25))+SUMPRODUCT((Assumptions!$E$130:$E$149<0)+(Assumptions!$G$130:$G$149<0)+(Assumptions!$G$130:$G$149>1)+(Assumptions!$H$130:$H$149<0)+(Assumptions!$I$130:$I$149<0)+(Assumptions!$J$130:$J$149<0)+(Assumptions!$F$130:$F$149<0)+((Assumptions!$D$130:$D$149="CPC")*(Assumptions!$F$130:$F$149>1)))+(Assumptions!$D$48<0)+(Assumptions!$D$48>=1)+(Assumptions!$D$20<Assumptions!$D$7)+(Assumptions!$D$20>Assumptions!$D$8)+(Assumptions!$D$8<=Assumptions!$D$7)+(Assumptions!$D$91>=Assumptions!$D$89)+(Assumptions!$D$92<Assumptions!$D$90)=0,"✓ all inputs valid","✗ invalid input: "&IF(((Assumptions!$D$10<0)+(Assumptions!$D$10>1)+(Assumptions!$D$52<0)+(Assumptions!$D$52>1)+(Assumptions!$D$50<0)+(Assumptions!$D$50>1)+(Assumptions!$D$64<0)+(Assumptions!$D$64>1)+(Assumptions!$D$157<0)+(Assumptions!$D$157>1)+(Assumptions!$D$158<0)+(Assumptions!$D$158>1)+(Assumptions!$D$163<0)+(Assumptions!$D$163>1)+(Assumptions!$D$168<0)+(Assumptions!$D$168>1)+(Assumptions!$D$170<0)+(Assumptions!$D$170>1)+(Assumptions!$D$174<0)+(Assumptions!$D$174>1)+(Assumptions!$D$93<0)+(Assumptions!$D$93>1)+(Assumptions!$D$94<0)+(Assumptions!$D$94>1)+(Assumptions!$D$95<0)+(Assumptions!$D$95>1)+(Assumptions!$D$89<0)+(Assumptions!$D$89>1)+(Assumptions!$D$91<0)+(Assumptions!$D$91>1)+(Assumptions!$D$29<0)+(Assumptions!$D$29>1)+(Assumptions!$D$30<0)+(Assumptions!$D$30>1)+(Assumptions!$D$31<0)+(Assumptions!$D$31>1)+(Assumptions!$D$32<0)+(Assumptions!$D$32>1)+(Assumptions!$D$33<0)+(Assumptions!$D$33>1)+(Assumptions!$D$34<0)+(Assumptions!$D$34>1)+(Assumptions!$D$35<0)+(Assumptions!$D$35>1)+(Assumptions!$D$36<0)+(Assumptions!$D$36>1)+(Assumptions!$D$37<0)+(Assumptions!$D$37>1)+(Assumptions!$D$38<0)+(Assumptions!$D$38>1)+(Assumptions!$D$39<0)+(Assumptions!$D$39>1)+(Assumptions!$D$40<0)+(Assumptions!$D$40>1)+(Assumptions!$D$41<0)+(Assumptions!$D$41>1)+(Assumptions!$D$42<0)+(Assumptions!$D$42>1)+(Assumptions!$D$43<0)+(Assumptions!$D$43>1)+(Assumptions!$D$44<0)+(Assumptions!$D$44>1)+(Assumptions!$D$53<0)+(Assumptions!$D$53>1)+(Assumptions!$D$54<0)+(Assumptions!$D$54>1)+(Assumptions!$D$55<0)+(Assumptions!$D$55>1)+(Assumptions!$D$56<0)+(Assumptions!$D$56>1)+(Assumptions!$D$57<0)+(Assumptions!$D$57>1)+(Assumptions!$D$58<0)+(Assumptions!$D$58>1)+(Assumptions!$D$59<0)+(Assumptions!$D$59>1)+(Assumptions!$D$60<0)+(Assumptions!$D$60>1)+(Assumptions!$D$61<0)+(Assumptions!$D$61>1)+(Assumptions!$D$62<0)+(Assumptions!$D$62>1)+(Assumptions!$D$63<0)+(Assumptions!$D$63>1)+(Assumptions!$D$72<0)+(Assumptions!$D$72>1)+(Assumptions!$D$73<0)+(Assumptions!$D$73>1)+(Assumptions!$D$74<0)+(Assumptions!$D$74>1)+(Assumptions!$D$75<0)+(Assumptions!$D$75>1)+(Assumptions!$D$96<0)+(Assumptions!$D$96>1)+(Assumptions!$D$99<0)+(Assumptions!$D$99>1)+(Assumptions!$D$100<0)+(Assumptions!$D$100>1)+(Assumptions!$D$101<0)+(Assumptions!$D$101>1)+(Assumptions!$D$102<0)+(Assumptions!$D$102>1)+(Assumptions!$D$108<0)+(Assumptions!$D$108>1)+(Assumptions!$D$109<0)+(Assumptions!$D$109>1)+(Assumptions!$D$110<0)+(Assumptions!$D$110>1)+(Assumptions!$D$111<0)+(Assumptions!$D$111>1)+(Assumptions!$D$112<0)+(Assumptions!$D$112>1)+(Assumptions!$D$113<0)+(Assumptions!$D$113>1)+(Assumptions!$D$115<0)+(Assumptions!$D$115>1)+(Assumptions!$D$121<0)+(Assumptions!$D$121>1)+(Assumptions!$D$122<0)+(Assumptions!$D$122>1)+(Assumptions!$D$123<0)+(Assumptions!$D$123>1))>0,"a share/rate is outside 0–100%; ","")&IF(((Assumptions!$D$9<0)+(Assumptions!$D$11<0)+(Assumptions!$D$12<0)+(Assumptions!$D$13<0)+(Assumptions!$D$14<0)+(Assumptions!$D$15<0)+(Assumptions!$D$19<0)+(Assumptions!$D$21<0)+(Assumptions!$D$22<0)+(Assumptions!$D$23<0)+(Assumptions!$D$24<0)+(Assumptions!$D$25<0)+(Assumptions!$D$49<0)+(Assumptions!$D$51<0)+(Assumptions!$D$68<0)+(Assumptions!$D$69<0)+(Assumptions!$D$70<0)+(Assumptions!$D$71<0)+(Assumptions!$D$76<0)+(Assumptions!$D$77<0)+(Assumptions!$D$78<0)+(Assumptions!$D$79<0)+(Assumptions!$D$83<0)+(Assumptions!$D$84<0)+(Assumptions!$D$85<0)+(Assumptions!$D$86<0)+(Assumptions!$D$87<0)+(Assumptions!$D$88<0)+(Assumptions!$D$90<0)+(Assumptions!$D$92<0)+(Assumptions!$D$97<0)+(Assumptions!$D$98<0)+(Assumptions!$D$103<0)+(Assumptions!$D$114<0)+(Assumptions!$D$116<0)+(Assumptions!$D$117<0)+(Assumptions!$D$118<0)+(Assumptions!$D$119<0)+(Assumptions!$D$120<0)+(Assumptions!$D$124<0)+(Assumptions!$D$125<0)+(Assumptions!$D$126<0)+(Assumptions!$D$153<0)+(Assumptions!$D$154<0)+(Assumptions!$D$155<0)+(Assumptions!$D$156<0)+(Assumptions!$D$159<0)+(Assumptions!$D$160<0)+(Assumptions!$D$161<0)+(Assumptions!$D$162<0)+(Assumptions!$D$164<0)+(Assumptions!$D$165<0)+(Assumptions!$D$166<0)+(Assumptions!$D$167<0)+(Assumptions!$D$169<0)+(Assumptions!$D$171<0)+(Assumptions!$D$172<0)+(Assumptions!$D$173<0)+(Assumptions!$D$175<0)+(Assumptions!$D$176<0)+(Assumptions!$D$177<0)+(Assumptions!$D$178<0)+(Assumptions!$D$179<0)+(Assumptions!$D$180<0)+(Assumptions!$D$181<0)+(Assumptions!$D$182<0))>0,"a count, cost or day value is negative; ","")&IF(((INT(Assumptions!$D$19)<>Assumptions!$D$19)+(INT(Assumptions!$D$21)<>Assumptions!$D$21)+(INT(Assumptions!$D$22)<>Assumptions!$D$22)+(INT(Assumptions!$D$23)<>Assumptions!$D$23)+(INT(Assumptions!$D$24)<>Assumptions!$D$24)+(INT(Assumptions!$D$25)<>Assumptions!$D$25))>0,"day inputs (T0, T2–T6) must be whole days; ","")&IF(SUMPRODUCT((Assumptions!$E$130:$E$149<0)+(Assumptions!$G$130:$G$149<0)+(Assumptions!$G$130:$G$149>1)+(Assumptions!$H$130:$H$149<0)+(Assumptions!$I$130:$I$149<0)+(Assumptions!$J$130:$J$149<0)+(Assumptions!$F$130:$F$149<0)+((Assumptions!$D$130:$D$149="CPC")*(Assumptions!$F$130:$F$149>1)))>0,"a channel input (Assumptions §7) is out of range; ","")&IF(OR(Assumptions!$D$48<0,Assumptions!$D$48>=1),"reserve share must be 0–99%; ","")&IF(OR(Assumptions!$D$20<Assumptions!$D$7,Assumptions!$D$20>Assumptions!$D$8),"last signing date must fall inside the campaign; ","")&IF(Assumptions!$D$8<=Assumptions!$D$7,"campaign end must be after its start; ","")&IF(OR(Assumptions!$D$91>=Assumptions!$D$89,Assumptions!$D$92<Assumptions!$D$90),"initiative kill thresholds must sit below pass thresholds (TK1 < TP1, TK2 ≥ TP2); ","")) -> ✓ all inputs valid
B20: Plan / schedule check (Weekly S15) | C20: =Weekly!S15 -> ✓ ties to plan
B22: Tabs: Assumptions (every input, its label and source link) → Funnel (Part 1, with the talent-pool check) → Channels (Part 2.2–2.3) → Initiatives (Part 3) → Budget (Part 2.4–2.5, with the budget-cut scenarios) → Weekly (phasing and cash) → Tracker (Part 4, live re-plan).

Sheet Assumptions
A1: Assumptions log = the model's only input sheet
A2: Blue cells on yellow are inputs: change them here and every other tab recalculates. Labels: Given = from the brief; Researched = read from, or calculated by stated arithmetic from, the linked source; Own estimate = my judgement, with the reason (and the benchmark it starts from, where there is one). Black (not blue) values are calculated.
A5: 1. Given in the brief
A6: ID | B6: Parameter | C6: Role / scope | D6: Value | E6: Unit | F6: Label | G6: Source / reasoning
A7: G1 | B7: Campaign start | C7: All | D7: 46315 | E7: date | F7: Given | G7: From the brief.
A8: G2 | B8: Campaign end / hire deadline (signed contract) | C8: All | D8: 46387 | E8: date | F8: Given | G8: From the brief.
A9: G3 | B9: Recruiter capacity: qualified applicants assessed per week | C9: All roles | D9: 55 | E9: per week | F9: Given | G9: From the brief.
A10: G4 | B10: Max share of mechatronics/mechanical hires from Polish sources | C10: Mechatronics | D10: 0.4 | E10: % | F10: Given | G10: From the brief. Polish hires need no work permit (EU free movement) and are insured and taxed in Germany. https://www.make-it-in-germany.com/en/working-in-germany/information-eu-citizens/print
A11: G5 | B11: Openings | C11: Electricians | D11: 30 | E11: hires | F11: Given | G11: From the brief.
A12: G6 | B12: Openings | C12: Mechatronics | D12: 45 | E12: hires | F12: Given | G12: From the brief.
A13: G7 | B13: Openings | C13: Automation | D13: 15 | E13: hires | F13: Given | G13: From the brief.
A14: G8 | B14: Openings | C14: Supervisors | D14: 10 | E14: hires | F14: Given | G14: From the brief.
A15: G9 | B15: Foreign electrical qualification recognition time (info only: makes foreign-trained electricians unhireable by 31 Dec) | C15: Electricians | D15: 2 | E15: months (min) | F15: Given | G15: From the brief, so I plan no foreign-trained electricians. Worth raising: for employees the trade is not legally regulated, which could open this route. https://www.anerkennung-in-deutschland.de/en/interest/finder/profession/62/profile
A17: 2. Hiring timeline (sets the last useful application date)
A18: ID | B18: Parameter | C18: Role / scope | D18: Value | E18: Unit | F18: Label | G18: Source / reasoning
A19: T0 | B19: Days from campaign start to first assessments | C19: All | D19: 2 | E19: days | F19: Own estimate | G19: Own estimate, not sourced: at launch there is no queue, so the first applicants and re-applicants are assessed within 2 days (SmartRecruiters' 6-day median review, T2, applies once a queue exists and sets the cut-off). If first assessments slip to 26 Oct, hires fall to ~92 (model run); 100 would then need 60 a week.
A20: T1 | B20: Last realistic contract-signing date | C20: All | D20: 46374 | E20: date | F20: Own estimate | G20: My choice: the last Friday before Christmas. Indeed job searches fall to 45% below the 1–15 Dec average over the holidays (Indeed Hiring Lab). https://hiringlab.indeed.com/de/blog/2025/02/17/der-stellenmarkt-startet-unausgewogen-in-das-neue-jahr/
A21: T2 | B21: Days: application → recruiter assessment of a qualified applicant | C21: All | D21: 6 | E21: days | F21: Researched | G21: Own estimate: SmartRecruiters 2025 global median is 6 days to review (Germany 8); I assume the client keeps the global pace, an ask. Slide 1 shows the German-pace downside (~92 hires). https://ta.smartrecruiters.com/rs/664-NIC-529/images/Germany%20Recruiting%20Benchmarks%202025%20Report%20DE.pdf
A22: T3 | B22: Days: recruiter assessment → technical interview/test done | C22: All | D22: 8 | E22: days | F22: Own estimate | G22: Own estimate: global median 14 days application → interview minus the 6 above (Germany 20 − 8 = 12); same commitment as T2. https://ta.smartrecruiters.com/rs/664-NIC-529/images/Germany%20Recruiting%20Benchmarks%202025%20Report%20DE.pdf
A23: T4 | B23: Days: interview → written offer | C23: All | D23: 3 | E23: days | F23: Own estimate | G23: My ask to the client: written offer within 3 working days. No public benchmark exists for this step.
A24: T5 | B24: Days: offer → signed contract | C24: All | D24: 7 | E24: days | F24: Own estimate | G24: One-week offer validity; candidates take ~9 days on average to decide (NACE 2025). https://www.naceweb.org/talent-acquisition/trends-and-predictions/employers-make-more-offers-as-student-acceptance-rate-rises-response-time-shortens
A25: T6 | B25: Extra days for supervisors (second round with plant management) | C25: Supervisors | D25: 7 | E25: days | F25: Own estimate | G25: Supervisors have one extra round with plant management (about a week).
A27: 3. Funnel rates by role (Part 1)
A28: ID | B28: Parameter | C28: Role / scope | D28: Value | E28: Unit | F28: Label | G28: Source / reasoning
A29: QE | B29: Application → qualified (baseline, all channels) | C29: Electricians | D29: 0.25 | E29: % | F29: Researched | G29: IAB 2026 chart: production jobs get 12 applications per vacancy, 3 suitable (25%); 28% across all jobs; 23% for specialist roles. https://iab-forum.de/iab-stellenerhebung-2-2026-fast-drei-von-vier-bewerbungen-sind-aus-betrieblicher-sicht-ungeeignet/
A30: QM | B30: Application → qualified (baseline, all channels) | C30: Mechatronics | D30: 0.25 | E30: % | F30: Researched | G30: IAB 2026 chart: production jobs get 12 applications per vacancy, 3 suitable (25%); 28% across all jobs; 23% for specialist roles. https://iab-forum.de/iab-stellenerhebung-2-2026-fast-drei-von-vier-bewerbungen-sind-aus-betrieblicher-sicht-ungeeignet/
A31: QA | B31: Application → qualified (baseline, all channels) | C31: Automation | D31: 0.25 | E31: % | F31: Researched | G31: IAB 2026 chart: production jobs get 12 applications per vacancy, 3 suitable (25%); 28% across all jobs; 23% for specialist roles. https://iab-forum.de/iab-stellenerhebung-2-2026-fast-drei-von-vier-bewerbungen-sind-aus-betrieblicher-sicht-ungeeignet/
A32: QS | B32: Application → qualified (baseline, all channels) | C32: Supervisors | D32: 0.23 | E32: % | F32: Researched | G32: IAB 2026 chart: production jobs get 12 applications per vacancy, 3 suitable (25%); 28% across all jobs; 23% for specialist roles. https://iab-forum.de/iab-stellenerhebung-2-2026-fast-drei-von-vier-bewerbungen-sind-aus-betrieblicher-sicht-ungeeignet/
A33: PE | B33: Qualified → passed assessment | C33: Electricians | D33: 0.5 | E33: % | F33: Own estimate | G33: Gem 2025: ~35% of candidates brought onsite get offers (mostly US tech). Set higher (50%) because only pre-qualified people reach this step. https://lp.gem.com/rs/972-IVV-330/images/2025%20Recruiting%20Benchmarks%20-%20Gem.pdf
A34: PM | B34: Qualified → passed assessment | C34: Mechatronics | D34: 0.55 | E34: % | F34: Own estimate | G34: Gem 2025: ~35% of onsite candidates get offers. Set at 55%: most common trade, the assessment is routine for it. https://lp.gem.com/rs/972-IVV-330/images/2025%20Recruiting%20Benchmarks%20-%20Gem.pdf
A35: PA | B35: Qualified → passed assessment | C35: Automation | D35: 0.45 | E35: % | F35: Own estimate | G35: Gem 2025: ~35% of onsite candidates get offers. Set at 45%: PLC skills are tested hard. https://lp.gem.com/rs/972-IVV-330/images/2025%20Recruiting%20Benchmarks%20-%20Gem.pdf
A36: PS | B36: Qualified → passed assessment | C36: Supervisors | D36: 0.4 | E36: % | F36: Own estimate | G36: Gem 2025: ~35% of onsite candidates get offers. Set at 40%: leadership is assessed on top of trade skills. https://lp.gem.com/rs/972-IVV-330/images/2025%20Recruiting%20Benchmarks%20-%20Gem.pdf
A37: OE | B37: Passed → offer made | C37: Electricians | D37: 0.9 | E37: % | F37: Own estimate | G37: My estimate: ~10% drop out after passing (references, pay, shifts), 15% for supervisors. No public figure exists.
A38: OM | B38: Passed → offer made | C38: Mechatronics | D38: 0.9 | E38: % | F38: Own estimate | G38: My estimate: ~10% drop out after passing (references, pay, shifts), 15% for supervisors. No public figure exists.
A39: OA | B39: Passed → offer made | C39: Automation | D39: 0.9 | E39: % | F39: Own estimate | G39: My estimate: ~10% drop out after passing (references, pay, shifts), 15% for supervisors. No public figure exists.
A40: OS | B40: Passed → offer made | C40: Supervisors | D40: 0.85 | E40: % | F40: Own estimate | G40: My estimate: ~10% drop out after passing (references, pay, shifts), 15% for supervisors. No public figure exists.
... A44: AS | B44: Offer → signed contract | C44: Supervisors | D44: 0.7 | E44: % | F44: Own estimate | G44: Königsteiner 2022: 47% accepted vs 14% declined after an offer → ~77% acceptance. I use 70–75%: shift work and competing offers. https://www.lebensmittelzeitung.net/handel/karriere/rekrutierung-bewerber-sagen-haeufiger-ab-166449
A46: 4. Budget policy and weekly phasing (Part 2)
A47: ID | B47: Parameter | C47: Role / scope | D47: Value | E47: Unit | F47: Label | G47: Source / reasoning
A48: B1 | B48: Reserve held back (share of total budget) | C48: All | D48: 0.15 | E48: % | F48: Own estimate | G48: 15% buffer, in the 10–20% range used for risky projects; released only on results. https://mastt.com/blogs/construction-contingency
...

Sheet Funnel
A1: Part 1 — Funnel by role (work back from openings)
A2: How: qualified needed = openings ÷ (pass × offer × accept); applications needed = qualified ÷ share qualified. Rates from Assumptions §3. 'Qualified' = right trade qualification + English or German + accepts shifts (brief).
A4: Role | B4: Openings | C4: App → qualified | D4: Qualified → passed | E4: Passed → offer | F4: Offer → signed | G4: Qualified → signed | H4: App → signed | I4: Offers needed | J4: Passed needed | K4: Qualified needed | L4: Applications needed (baseline Q) | M4: Applications in plan (channel mix) | N4: Blended Q in plan | O4: Qualified in plan | P4: Share of assessment slots
A5: Electricians | B5: =Assumptions!$D$11 -> 30 | C5: =Assumptions!$D$29 -> 0.25 | D5: =Assumptions!$D$33 -> 0.5 | E5: =Assumptions!$D$37 -> 0.9 | F5: =Assumptions!$D$41 -> 0.7 | G5: =D5*E5*F5 -> 0.315 | H5: =C5*G5 -> 0.07875 | I5: =IF(F5>0,B5/F5,0) -> 42.857143 | J5: =IF(E5>0,I5/E5,0) -> 47.619048 | K5: =IF(D5>0,J5/D5,0) -> 95.238095 | L5: =IF(C5>0,K5/C5,0) -> 380.95238 | M5: =SUMIFS(Channels!$W:$W,Channels!$C:$C,A5) -> 414.27263 | N5: =IF(M5>0,O5/M5,0) -> 0.23234239 | O5: =SUMIFS(Channels!$V:$V,Channels!$C:$C,A5) -> 96.253095 | P5: =IF($B$22>0,O5/$B$22,0) -> 0.30625985
A6: Mechatronics | B6: =Assumptions!$D$12 -> 45 | C6: =Assumptions!$D$30 -> 0.25 | D6: =Assumptions!$D$34 -> 0.55 | E6: =Assumptions!$D$38 -> 0.9 | F6: =Assumptions!$D$42 -> 0.75 | G6: =D6*E6*F6 -> 0.37125 | H6: =C6*G6 -> 0.0928125 | I6: =IF(F6>0,B6/F6,0) -> 60 | J6: =IF(E6>0,I6/E6,0) -> 66.666667 | K6: =IF(D6>0,J6/D6,0) -> 121.21212 | L6: =IF(C6>0,K6/C6,0) -> 484.84848 | M6: =SUMIFS(Channels!$W:$W,Channels!$C:$C,A6) -> 662.46932 | N6: =IF(M6>0,O6/M6,0) -> 0.17928848 | O6: =SUMIFS(Channels!$V:$V,Channels!$C:$C,A6) -> 118.77312 | P6: =IF($B$22>0,O6/$B$22,0) -> 0.37791448
A7: Automation | B7: =Assumptions!$D$13 -> 15 | C7: =Assumptions!$D$31 -> 0.25 | D7: =Assumptions!$D$35 -> 0.45 | E7: =Assumptions!$D$39 -> 0.9 | F7: =Assumptions!$D$43 -> 0.7 | G7: =D7*E7*F7 -> 0.2835 | H7: =C7*G7 -> 0.070875 | I7: =IF(F7>0,B7/F7,0) -> 21.428571 | J7: =IF(E7>0,I7/E7,0) -> 23.809524 | K7: =IF(D7>0,J7/D7,0) -> 52.910053 | L7: =IF(C7>0,K7/C7,0) -> 211.64021 | M7: =SUMIFS(Channels!$W:$W,Channels!$C:$C,A7) -> 226.47133 | N7: =IF(M7>0,O7/M7,0) -> 0.22883935 | O7: =SUMIFS(Channels!$V:$V,Channels!$C:$C,A7) -> 51.825553 | P7: =IF($B$22>0,O7/$B$22,0) -> 0.16489949
A8: Supervisors | B8: =Assumptions!$D$14 -> 10 | C8: =Assumptions!$D$32 -> 0.23 | D8: =Assumptions!$D$36 -> 0.4 | E8: =Assumptions!$D$40 -> 0.85 | F8: =Assumptions!$D$44 -> 0.7 | G8: =D8*E8*F8 -> 0.238 | H8: =C8*G8 -> 0.05474 | I8: =IF(F8>0,B8/F8,0) -> 14.285714 | J8: =IF(E8>0,I8/E8,0) -> 16.806723 | K8: =IF(D8>0,J8/D8,0) -> 42.016807 | L8: =IF(C8>0,K8/C8,0) -> 182.68177 | M8: =SUMIFS(Channels!$W:$W,Channels!$C:$C,A8) -> 191.36195 | N8: =IF(M8>0,O8/M8,0) -> 0.21488758 | O8: =SUMIFS(Channels!$V:$V,Channels!$C:$C,A8) -> 41.121307 | P8: =IF($B$22>0,O8/$B$22,0) -> 0.13084052
A9: Total | B9: =SUM(B5:B8) -> 100 | G9: =IF(K9>0,B9/K9,0) -> 0.32115402 | I9: =SUM(I5:I8) -> 138.57143 | J9: =SUM(J5:J8) -> 154.90196 | K9: =SUM(K5:K8) -> 311.37708 | L9: =SUM(L5:L8) -> 1260.1228 | M9: =SUM(M5:M8) -> 1494.5752 | N9: =IF(M9>0,O9/M9,0) -> 0.2060606 | O9: =SUM(O5:O8) -> 307.97308 | P9: =IF($B$22>0,O9/$B$22,0) -> 0.97991433
A10: Qualified needed (col K) uses role averages; 'Qualified in plan' (col O) reflects the actual channel mix incl. better/worse downstream conversion of initiatives. Capacity is checked on col O.
A12: Timeline and recruiter capacity (Part 1.3)
A13: First assessment date | B13: =Assumptions!$D$7+Assumptions!$D$19 -> 46317
A14: Last signing date | B14: =Assumptions!$D$20 -> 46374
A15: Days assessment → signed (E/M/A) | B15: =Assumptions!$D$22+Assumptions!$D$23+Assumptions!$D$24 -> 18
A16: Days assessment → signed (Supervisors) | B16: =B15+Assumptions!$D$25 -> 25
A17: Last assessment date (E/M/A) | B17: =B14-B15 -> 46356
A18: Last assessment date (Supervisors) | B18: =B14-B16 -> 46349
A19: Last useful application date (E/M/A) | B19: =B17-Assumptions!$D$21 -> 46350
A20: Last useful application date (Supervisors) | B20: =B18-Assumptions!$D$21 -> 46343
A21: Assessment window (days, E/M/A) | B21: =MAX(0,B17-B13+1) -> 40
A22: Assessment slots available (capacity × weeks) | B22: =Assumptions!$D$9*B21/7 -> 314.28571
A23: Qualified applicants in plan | B23: =O9 -> 307.97308
A24: Slot utilisation | B24: =IF(B22>0,B23/B22,IF(B23>0,9.99,0)) -> 0.97991433 | C24: =IF(B24>1,"OVER CAPACITY – plan cannot be assessed",IF(B24>Assumptions!$D$101,"Tight: little headroom","OK")) -> Tight: little headroom
A25: Hires per qualified applicant (plan mix) | B25: =IF(O9>0,Channels!U35/O9,0) -> 0.32470371
A26: Max hires the 55/week limit allows before 31 Dec | B26: =B22*B25 -> 102.04974 | C26: If every slot is filled at the plan's conversion; above 100 = headroom.
A28: Which role is hardest to fill? (Part 1.3)
A29: Role | B29: Openings | C29: Qualified needed (plan) | D29: Hire capacity of all channels at plan rates | E29: Coverage (capacity ÷ openings) | F29: Reachable qualified pool (pool check below) | G29: Qualified needed ÷ reachable pool (excl. I2, pool check below) | H29: Highest cost per hire we must buy (beyond tests) | I29: Polish route allowed? | J29: Foreign-trained route by 31 Dec? | K29: Coverage without the unproven I2 initiative | L29: Ranking helper (roles with openings)
A30: Electricians | B30: =B5 -> 30 | C30: =O5 -> 96.253095 | D30: =SUMIFS(Channels!$N:$N,Channels!$C:$C,A30) -> 110.22165 | E30: =IF(B30>0,D30/B30,0) -> 3.674055 | F30: =Funnel!F58 -> 569 | G30: =Funnel!H58 -> 0.11731651 | H30: =_xlfn.MAXIFS(Channels!$P:$P,Channels!$C:$C,A30,Channels!$AI:$AI,">0") -> 2271.6049 | I30: No | J30: No – recognition takes 2–4 months | K30: =IF(B30>0,(D30-SUMIFS(Channels!$N:$N,Channels!$A:$A,"I2-E",Channels!$C:$C,A30))/B30,0) -> 3.39528 | L30: =IF(B30>0,K30,1000000000) -> 3.39528
A31: Mechatronics | B31: =B6 -> 45 | C31: =O6 -> 118.77312 | D31: =SUMIFS(Channels!$N:$N,Channels!$C:$C,A31) -> 551.69007 | E31: =IF(B31>0,D31/B31,0) -> 12.259779 | F31: =Funnel!F59 -> 2932 | G31: =Funnel!H59 -> 0.04050925 | H31: =_xlfn.MAXIFS(Channels!$P:$P,Channels!$C:$C,A31,Channels!$AI:$AI,">0") -> 1927.4224 | I31: Yes (≤40%) | J31: Yes (no recognition gate in brief) | K31: =IF(B31>0,(D31-SUMIFS(Channels!$N:$N,Channels!$A:$A,"I2-E",Channels!$C:$C,A31))/B31,0) -> 12.259779 | L31: =IF(B31>0,K31,1000000000) -> 12.259779
A32: Automation | B32: =B7 -> 15 | C32: =O7 -> 51.825553 | D32: =SUMIFS(Channels!$N:$N,Channels!$C:$C,A32) -> 47.908523 | E32: =IF(B32>0,D32/B32,0) -> 3.1939016 | F32: =Funnel!F60 -> 236 | G32: =Funnel!H60 -> 0.2195998 | H32: =_xlfn.MAXIFS(Channels!$P:$P,Channels!$C:$C,A32,Channels!$AI:$AI,">0") -> 1504.9971 | I32: No | J32: Yes (no recognition gate in brief) | K32: =IF(B32>0,(D32-SUMIFS(Channels!$N:$N,Channels!$A:$A,"I2-E",Channels!$C:$C,A32))/B32,0) -> 3.1939016 | L32: =IF(B32>0,K32,1000000000) -> 3.1939016
A33: Supervisors | B33: =B8 -> 10 | C33: =O8 -> 41.121307 | D33: =SUMIFS(Channels!$N:$N,Channels!$C:$C,A33) -> 39.749451 | E33: =IF(B33>0,D33/B33,0) -> 3.9749451 | F33: =Funnel!F61 -> 246 | G33: =Funnel!H61 -> 0.16715978 | H33: =_xlfn.MAXIFS(Channels!$P:$P,Channels!$C:$C,A33,Channels!$AI:$AI,">0") -> 1948.6055 | I33: No | J33: Yes (no recognition gate in brief) | K33: =IF(B33>0,(D33-SUMIFS(Channels!$N:$N,Channels!$A:$A,"I2-E",Channels!$C:$C,A33))/B33,0) -> 3.9749451 | L33: =IF(B33>0,K33,1000000000) -> 3.9749451
A35: ="Hardest role: "&Summary!C16&", the highest in column H. Why: industrial electricians are the scarcest trade in Brandenburg (KOFA 2026: 85.7% of vacancies have no suitable unemployed candidate vs 41.4% overall, https://www.kofa.de/media/Publikationen/Laendersteckbriefe/Brandenburg.pdf), and they have no Polish or foreign-trained route under the brief. Automation’s pool and channel coverage are tighter (column G: "&TEXT(G32,"0%")&" of reachable people vs "&TEXT(G30,"0%")&"; column E: "&TEXT(E32,"0.0")&"× vs "&TEXT(E30,"0.0")&"×), but it needs only "&B32&" hires and its last hire is cheaper, so it is watched in the weekly pool check rather than ranked hardest." -> Hardest role: Electricians (last hire costs €2,272), the highest in column H. Why: industrial electricians are the scarcest trade in Brandenburg (KOFA 2026: 85.7% of vacancies have no suitable unemployed candidate vs 41.4% overall, https://www.kofa.de/media/Publikationen/Laendersteckbriefe/Brandenburg.pdf), and they have no Polish or foreign-trained route under the brief. Automation’s pool and channel coverage are tighter (column G: 22% of reachable people vs 12%; column E: 3.2× vs 3.7×), but it needs only 15 hires and its last hire is cheaper, so it is watched in the weekly pool check rather than ranked hardest.
A39: Sensitivity: each assumption 30% worse (Part 1.4)
A40: Stress size: | B40: =Assumptions!$D$64 -> 0.3
A41: Assumption made 30% worse | B41: Qualified applicants needed | C41: Slot utilisation | D41: Hires possible before 31 Dec | E41: Hires lost vs 100 | F41: Spend needed (€, approx.: all variable spend scaled, channel caps ignored) | G41: Change in media | H41: Why
A42: Base case | B42: =O9 -> 307.97308 | C42: =IF(($B$22)>0,B42/($B$22),IF(B42>0,9.99,0)) -> 0.97991433 | D42: =MIN($B$9,IF(B42>0,$B$22/B42*$B$9,$B$9),MIN(B5,D30*1)+MIN(B6,D31*1)+MIN(B7,D32*1)+MIN(B8,D33*1)) -> 100 | E42: =$B$9-D42 -> 0 | F42: =Budget!$C$7*1 -> 102255.85 | G42: =IF(Budget!$C$7>0,F42/Budget!$C$7-1,0) -> 0 | H42: Plan as built.
A43: Qualified → signed (assessment pass rate) ×0.7 | B43: =O9/(1-$B$40) -> 439.96154 | C43: =IF(($B$22)>0,B43/($B$22),IF(B43>0,9.99,0)) -> 1.3998776 | D43: =MIN($B$9,IF(B43>0,$B$22/B43*$B$9,$B$9),MIN(B5,D30*(1-$B$40))+MIN(B6,D31*(1-$B$40))+MIN(B7,D32*(1-$B$40))+MIN(B8,D33*(1-$B$40))) -> 71.434816 | E43: =$B$9-D43 -> 28.565184 | F43: =Budget!$C$7*1/(1-$B$40) -> 146079.78 | G43: =IF(Budget!$C$7>0,F43/Budget!$C$7-1,0) -> 0.42857143 | H43: Each qualified applicant yields 30% fewer hires → 43% more qualified needed, but slots are fixed at 55/week.
A44: Offer acceptance ×0.7 | B44: =O9/(1-$B$40) -> 439.96154 | C44: =IF(($B$22)>0,B44/($B$22),IF(B44>0,9.99,0)) -> 1.3998776 | D44: =MIN($B$9,IF(B44>0,$B$22/B44*$B$9,$B$9),MIN(B5,D30*(1-$B$40))+MIN(B6,D31*(1-$B$40))+MIN(B7,D32*(1-$B$40))+MIN(B8,D33*(1-$B$40))) -> 71.434816 | E44: =$B$9-D44 -> 28.565184 | F44: =Budget!$C$7*1/(1-$B$40) -> 146079.78 | G44: =IF(Budget!$C$7>0,F44/Budget!$C$7-1,0) -> 0.42857143 | H44: Same arithmetic as pass rate: it also sits between the capacity limit and the hire.
A45: Application → qualified ×0.7 | B45: =O9 -> 307.97308 | C45: =IF(($B$22)>0,B45/($B$22),IF(B45>0,9.99,0)) -> 0.97991433 | D45: =MIN($B$9,IF(B45>0,$B$22/B45*$B$9,$B$9),MIN(B5,D30*(1-$B$40))+MIN(B6,D31*(1-$B$40))+MIN(B7,D32*(1-$B$40))+MIN(B8,D33*(1-$B$40))) -> 100 | E45: =$B$9-D45 -> 0 | F45: =Budget!$C$7*1/(1-$B$40) -> 146079.78 | G45: =IF(Budget!$C$7>0,F45/Budget!$C$7-1,0) -> 0.42857143 | H45: Costs 43% more per qualified; slots unaffected; channels run out sooner (electricians first).
A46: Cost per application ×1.3 | B46: =O9 -> 307.97308 | C46: =IF(($B$22)>0,B46/($B$22),IF(B46>0,9.99,0)) -> 0.97991433 | D46: =MIN($B$9,IF(B46>0,$B$22/B46*$B$9,$B$9),MIN(B5,D30*1)+MIN(B6,D31*1)+MIN(B7,D32*1)+MIN(B8,D33*1)) -> 100 | E46: =$B$9-D46 -> 0 | F46: =Budget!$C$7*(1+$B$40) -> 132932.6 | G46: =IF(Budget!$C$7>0,F46/Budget!$C$7-1,0) -> 0.3 | H46: Pure money: +30% media, no effect on hires if the money is there.
A47: Recruiter capacity ×0.7 (≈38/week), given in the brief, shown for context | B47: =O9 -> 307.97308 | C47: =IF(($B$22*(1-$B$40))>0,B47/($B$22*(1-$B$40)),IF(B47>0,9.99,0)) -> 1.3998776 | D47: =MIN($B$9,IF(B47>0,$B$22*(1-$B$40)/B47*$B$9,$B$9),MIN(B5,D30*1)+MIN(B6,D31*1)+MIN(B7,D32*1)+MIN(B8,D33*1)) -> 71.434816 | E47: =$B$9-D47 -> 28.565184 | F47: =Budget!$C$7*1 -> 102255.85 | G47: =IF(Budget!$C$7>0,F47/Budget!$C$7-1,0) -> 0 | H47: Fewer slots: hires capped by capacity. Not ranked: 55/week is given, not assumed.
...

Sheet Initiatives
A1: Part 3 — New sources beyond the usual paid channels (maths feeds the Channels tab)
A2: How: people reachable × share who apply = applications; × share qualified × qualified → signed = hires; cost ÷ hires = cost per hire.
A3: I1 · Talent rediscovery (past applicants in client ATS) + employee referral sprint — built for electricians, used for all roles
A4: Line | B4: Electricians | C4: Mechatronics | D4: Automation | E4: Supervisors | F4: Total
A5: I1a Past qualified applicants in ATS | B5: =Assumptions!$D$153 -> 65 | C5: =Assumptions!$D$154 -> 76 | D5: =Assumptions!$D$155 -> 38 | E5: =Assumptions!$D$156 -> 32 | F5: =SUM(B5:E5) -> 211
A6: I1a Re-application rate | B6: =Assumptions!$D$157 -> 0.12 | C6: =Assumptions!$D$157 -> 0.12 | D6: =Assumptions!$D$157 -> 0.12 | E6: =Assumptions!$D$157 -> 0.12
A7: I1a Re-applications (max) | B7: =B5*B6 -> 7.8 | C7: =C5*C6 -> 9.12 | D7: =D5*D6 -> 4.56 | E7: =E5*E6 -> 3.84 | F7: =SUM(B7:E7) -> 25.32
A8: I1a Share qualified | B8: =Assumptions!$D$158 -> 0.5 | C8: =Assumptions!$D$158 -> 0.5 | D8: =Assumptions!$D$158 -> 0.5 | E8: =Assumptions!$D$158 -> 0.5
A9: I1 Qualified → signed (role × adj.) | B9: =Funnel!$G$5*Assumptions!$D$166 -> 0.36225 | C9: =Funnel!$G$6*Assumptions!$D$166 -> 0.4269375 | D9: =Funnel!$G$7*Assumptions!$D$166 -> 0.326025 | E9: =Funnel!$G$8*Assumptions!$D$166 -> 0.2737
A10: I1a Messaging cost (records × €/contact) | B10: =B5*Assumptions!$D$164 -> 19.5 | C10: =C5*Assumptions!$D$164 -> 22.8 | D10: =D5*Assumptions!$D$164 -> 11.4 | E10: =E5*Assumptions!$D$164 -> 9.6 | F10: =SUM(B10:E10) -> 63.3
A11: I1a Cost per application (→ Channels) | B11: =IF(B7>0,B10/B7,0) -> 2.5 | C11: =IF(C7>0,C10/C7,0) -> 2.5 | D11: =IF(D7>0,D10/D7,0) -> 2.5 | E11: =IF(E7>0,E10/E7,0) -> 2.5 | G11: ="≈"&TEXT(B11,"€0.00")&" per application: messaging is nearly free; the scarce input is the client’s ATS export." -> ≈€2.50 per application: messaging is nearly free; the scarce input is the client’s ATS export.
A12: I1a Hires if fully used | B12: =B7*B8*B9 -> 1.412775 | C12: =C7*C8*C9 -> 1.946835 | D12: =D7*D8*D9 -> 0.743337 | E12: =E7*E8*E9 -> 0.525504 | F12: =SUM(B12:E12) -> 4.628451
A13: I1b Referral applications (max) | B13: =Assumptions!$D$159 -> 20 | C13: =Assumptions!$D$160 -> 26 | D13: =Assumptions!$D$161 -> 11 | E13: =Assumptions!$D$162 -> 9 | F13: =SUM(B13:E13) -> 66
A14: I1b Share qualified | B14: =Assumptions!$D$163 -> 0.45 | C14: =Assumptions!$D$163 -> 0.45 | D14: =Assumptions!$D$163 -> 0.45 | E14: =Assumptions!$D$163 -> 0.45
A15: I1b Hires if fully used | B15: =B13*B14*B9 -> 3.26025 | C15: =C13*C14*C9 -> 4.9951688 | D15: =D13*D14*D9 -> 1.6138237 | E15: =E13*E14*E9 -> 1.108485 | F15: =SUM(B15:E15) -> 10.977728
A16: I1b Referral bonuses at full use (hires × bonus) | B16: =B15*Assumptions!$D$165 -> 3260.25 | C16: =C15*Assumptions!$D$165 -> 4995.1687 | D16: =D15*Assumptions!$D$165 -> 1613.8238 | E16: =E15*Assumptions!$D$165 -> 1108.485 | F16: =SUM(B16:E16) -> 10977.728
A17: I1b Expected bonus cost per application (→ Channels) | B17: =IF(B13>0,B16/B13,0) -> 163.0125 | C17: =IF(C13>0,C16/C13,0) -> 192.12187 | D17: =IF(D13>0,D16/D13,0) -> 146.71125 | E17: =IF(E13>0,E16/E13,0) -> 123.165 | G17: Bonus is only paid when a referred hire signs; shown per application so it ranks against paid channels.
A18: I1 Total hires if fully used | B18: =B12+B15 -> 4.673025 | C18: =C12+C15 -> 6.9420037 | D18: =D12+D15 -> 2.3571607 | E18: =E12+E15 -> 1.633989 | F18: =SUM(B18:E18) -> 15.606179
A19: I1 Total cost if fully used | B19: =B10+B16 -> 3279.75 | C19: =C10+C16 -> 5017.9688 | D19: =D10+D16 -> 1625.2238 | E19: =E10+E16 -> 1118.085 | F19: =SUM(B19:E19) -> 11041.028
A20: I1 Cost per hire | B20: =IF(B18>0,B19/B18,0) -> 701.8473 | C20: =IF(C18>0,C19/C18,0) -> 722.84155 | D20: =IF(D18>0,D19/D18,0) -> 689.48363 | E20: =IF(E18>0,E19/E18,0) -> 684.26715 | F20: =IF(F18>0,F19/F18,0) -> 707.47797
A23: I2 · 'Vom Handwerk in die Industrie' — construction electricians → plant maintenance (electricians only)
A24: Construction/Handwerk electricians within 75 km | B24: =Assumptions!$D$167 -> 10000
A25: Share who apply | B25: =Assumptions!$D$168 -> 0.0118
A26: Max applications | B26: =B24*B25 -> 118
A27: Cost per application | B27: =Assumptions!$D$169 -> 84
A28: Share qualified (client accepts profile) | B28: =Assumptions!$D$170 -> 0.25
A29: Qualified | B29: =B26*B28 -> 29.5
A30: Qualified → signed (electrician rate × I2A adjustment) | B30: =Funnel!$G$5*Assumptions!$D$171 -> 0.2835
A31: Expected hires if fully used | B31: =B29*B30 -> 8.36325
A32: Media at full use | B32: =B26*B27 -> 9912
A33: Fixed set-up | B33: =Assumptions!$D$172 -> 1200
A34: Cost per hire at full use | B34: =IF(B31>0,(B32+B33)/B31,0) -> 1328.6701
A37: I3 · Polish border corridor with a remote Polish-speaking pre-screener (mechatronics only, ≤40% of those hires)
A38: All-in cost per application (ads + pre-screen call) (→ Channels) | B38: =B44+B45 -> 18.75
A39: Share qualified after pre-screen | B39: =Assumptions!$D$174 -> 0.14
A40: Max applications | B40: =Assumptions!$D$175 -> 350
A41: Qualified → signed (mechatronics rate × I3A adjustment) | B41: =Funnel!$G$6*Assumptions!$D$176 -> 0.37125
A42: Hire cap from the 40% rule | B42: =Assumptions!$D$10*Assumptions!$D$12 -> 18
A43: Hires if fully used (capped) | B43: =MIN(B40*B39*B41,B42) -> 18
A44: Ad cost per application (Pracuj.pl, OLX Praca, PL-geo Meta) | B44: =Assumptions!$D$173 -> 14
...

Sheet Channels
A1: Part 2 — Channel × role economics and allocation (cheapest cost-per-hire first, until each role's openings are covered)
A2: How hires are bought: within each role, channels are used cheapest cost per hire first, each up to its volume cap, until openings are filled.
A3: Every paid channel first gets a €750 test in weeks 1–2; its hires count. Then only the remaining need is bought.
A4: ID | B4: Channel | C4: Role | D4: Type | E4: Basis | F4: Unit cost € | G4: Click→apply / apps per slot | H4: Cost per application | I4: Share qualified | J4: Max applications | K4: Qualified capacity | L4: Qualified → signed | M4: Downstream adj. | N4: Hire capacity | O4: Cost per qualified | P4: Cost per hire at capacity (incl. fixed) | Q4: Sort key | R4: Rank in role | S4: Remaining capacity of cheaper channels | T4: Need after all tests (openings – test hires) | U4: Hires (test + allocated) | V4: Qualified (total) | W4: Applications (total) | X4: Media € (incl. test tranche) | Y4: Fixed € | Z4: Test tranche wk 1–2 € | AA4: Total € | AB4: Planned cost per hire | AC4: Rank overall | AD4: Status | AE4: Test applications | AF4: Test qualified | AG4: Test hires | AH4: Hire capacity left after test | AI4: Hires allocated beyond test
A5: =Assumptions!A130 -> C01 | B5: =Assumptions!B130 -> Organic (Tesla careers, BA Jobbörse, Google for Jobs) | C5: =Assumptions!C130 -> Electricians | D5: Channel | E5: =Assumptions!D130 -> Free | F5: =Assumptions!E130 -> 0 | G5: =IF(E5="Free","",Assumptions!F130) | H5: =MAX(0,IF(OR(E5="CPC",E5="Slot"),IF(N(G5)>0,F5/G5,0),F5)) -> 0 | I5: =Assumptions!G130 -> 0.175 | J5: =IF(AND(OR(E5="CPC",E5="Slot"),NOT(N(G5)>0)),0,IF(E5="Slot",Assumptions!H130*G5,Assumptions!H130)) -> 105 | K5: =J5*I5 -> 18.375 | L5: =INDEX(Funnel!$G$5:$G$8,MATCH(C5,Funnel!$A$5:$A$8,0))*M5 -> 0.315 | M5: =Assumptions!I130 -> 1 | N5: =K5*L5 -> 5.788125 | O5: =IF(I5>0,H5/I5,0) -> 0 | P5: =IF(N5>0,(N5/L5/I5*H5+Assumptions!J130)/N5,0) -> 0 | Q5: =P5+ROW()/1000000 -> 5e-06 | R5: =SUMPRODUCT(($C$5:$C$34=C5)*($Q$5:$Q$34<Q5))+1 -> 1 | S5: =SUMPRODUCT(($C$5:$C$34=C5)*($Q$5:$Q$34<Q5)*$AH$5:$AH$34) -> 0 | T5: =INDEX(Funnel!$B$5:$B$8,MATCH(C5,Funnel!$A$5:$A$8,0))-SUMIFS($AG$5:$AG$34,$C$5:$C$34,C5) -> 29.150585 | U5: =AG5+AI5 -> 5.788125 | V5: =IF(L5>0,U5/L5,0) -> 18.375 | W5: =IF(I5>0,V5/I5,0) -> 105 | X5: =IF(E5="Slot",IF(N(G5)>0,ROUNDUP(W5/G5,0)*MAX(0,F5),0),W5*H5) -> 0 | Y5: =IF(U5>0,Assumptions!J130,0) -> 0 | Z5: =IF(AND(D5="Channel",OR(E5="CPC",E5="CPA"),INDEX(Funnel!$B$5:$B$8,MATCH(C5,Funnel!$A$5:$A$8,0))>0),MIN(Assumptions!$D$49,J5*H5,IF(I5*L5>0,INDEX(Funnel!$B$5:$B$8,MATCH(C5,Funnel!$A$5:$A$8,0))/SUMPRODUCT(($C$5:$C$34=C5)*($D$5:$D$34="Channel")*(($E$5:$E$34="CPC")+($E$5:$E$34="CPA")))/(I5*L5)*H5,0)),0) -> 0 | AA5: =X5+Y5 -> 0 | AB5: =IF(U5>0,(X5+Y5)/U5,"–") -> 0 | AC5: =SUMPRODUCT(--($Q$5:$Q$34<Q5))+1 -> 1 | AD5: =IF(AND(AH5>0,AI5>=AH5*0.999),"Used to capacity",IF(AI5>0,"Marginal (fills the gap)",IF(Z5>0,"Test only (wk 1–2)","Not used"))) -> Used to capacity | AE5: =IF(H5>0,Z5/H5,0) -> 0 | AF5: =AE5*I5 -> 0 | AG5: =AF5*L5 -> 0 | AH5: =MAX(0,N5-AG5) -> 5.788125 | AI5: =MIN(AH5,MAX(0,T5-S5)) -> 5.788125
A6: =Assumptions!A131 -> C02 | B6: =Assumptions!B131 -> Organic (Tesla careers, BA Jobbörse, Google for Jobs) | C6: =Assumptions!C131 -> Mechatronics | D6: Channel | E6: =Assumptions!D131 -> Free | F6: =Assumptions!E131 -> 0 | G6: =IF(E6="Free","",Assumptions!F131) | H6: =MAX(0,IF(OR(E6="CPC",E6="Slot"),IF(N(G6)>0,F6/G6,0),F6)) -> 0 | I6: =Assumptions!G131 -> 0.175 | J6: =IF(AND(OR(E6="CPC",E6="Slot"),NOT(N(G6)>0)),0,IF(E6="Slot",Assumptions!H131*G6,Assumptions!H131)) -> 158 | K6: =J6*I6 -> 27.65 | L6: =INDEX(Funnel!$G$5:$G$8,MATCH(C6,Funnel!$A$5:$A$8,0))*M6 -> 0.37125 | M6: =Assumptions!I131 -> 1 | N6: =K6*L6 -> 10.265063 | O6: =IF(I6>0,H6/I6,0) -> 0 | P6: =IF(N6>0,(N6/L6/I6*H6+Assumptions!J131)/N6,0) -> 0 | Q6: =P6+ROW()/1000000 -> 6e-06 | R6: =SUMPRODUCT(($C$5:$C$34=C6)*($Q$5:$Q$34<Q6))+1 -> 1 | S6: =SUMPRODUCT(($C$5:$C$34=C6)*($Q$5:$Q$34<Q6)*$AH$5:$AH$34) -> 0 | T6: =INDEX(Funnel!$B$5:$B$8,MATCH(C6,Funnel!$A$5:$A$8,0))-SUMIFS($AG$5:$AG$34,$C$5:$C$34,C6) -> 43.998904 | U6: =AG6+AI6 -> 10.265063 | V6: =IF(L6>0,U6/L6,0) -> 27.65 | W6: =IF(I6>0,V6/I6,0) -> 158 | X6: =IF(E6="Slot",IF(N(G6)>0,ROUNDUP(W6/G6,0)*MAX(0,F6),0),W6*H6) -> 0 | Y6: =IF(U6>0,Assumptions!J131,0) -> 0 | Z6: =IF(AND(D6="Channel",OR(E6="CPC",E6="CPA"),INDEX(Funnel!$B$5:$B$8,MATCH(C6,Funnel!$A$5:$A$8,0))>0),MIN(Assumptions!$D$49,J6*H6,IF(I6*L6>0,INDEX(Funnel!$B$5:$B$8,MATCH(C6,Funnel!$A$5:$A$8,0))/SUMPRODUCT(($C$5:$C$34=C6)*($D$5:$D$34="Channel")*(($E$5:$E$34="CPC")+($E$5:$E$34="CPA")))/(I6*L6)*H6,0)),0) -> 0 | AA6: =X6+Y6 -> 0 | AB6: =IF(U6>0,(X6+Y6)/U6,"–") -> 0 | AC6: =SUMPRODUCT(--($Q$5:$Q$34<Q6))+1 -> 2 | AD6: =IF(AND(AH6>0,AI6>=AH6*0.999),"Used to capacity",IF(AI6>0,"Marginal (fills the gap)",IF(Z6>0,"Test only (wk 1–2)","Not used"))) -> Used to capacity | AE6: =IF(H6>0,Z6/H6,0) -> 0 | AF6: =AE6*I6 -> 0 | AG6: =AF6*L6 -> 0 | AH6: =MAX(0,N6-AG6) -> 10.265063 | AI6: =MIN(AH6,MAX(0,T6-S6)) -> 10.265063
A7: =Assumptions!A132 -> C03 | B7: =Assumptions!B132 -> Organic (Tesla careers, BA Jobbörse, Google for Jobs) | C7: =Assumptions!C132 -> Automation | D7: Channel | E7: =Assumptions!D132 -> Free | F7: =Assumptions!E132 -> 0 | G7: =IF(E7="Free","",Assumptions!F132) | H7: =MAX(0,IF(OR(E7="CPC",E7="Slot"),IF(N(G7)>0,F7/G7,0),F7)) -> 0 | I7: =Assumptions!G132 -> 0.175 | J7: =IF(AND(OR(E7="CPC",E7="Slot"),NOT(N(G7)>0)),0,IF(E7="Slot",Assumptions!H132*G7,Assumptions!H132)) -> 53 | K7: =J7*I7 -> 9.275 | L7: =INDEX(Funnel!$G$5:$G$8,MATCH(C7,Funnel!$A$5:$A$8,0))*M7 -> 0.2835 | M7: =Assumptions!I132 -> 1 | N7: =K7*L7 -> 2.6294625 | O7: =IF(I7>0,H7/I7,0) -> 0 | P7: =IF(N7>0,(N7/L7/I7*H7+Assumptions!J132)/N7,0) -> 0 | Q7: =P7+ROW()/1000000 -> 7e-06 | R7: =SUMPRODUCT(($C$5:$C$34=C7)*($Q$5:$Q$34<Q7))+1 -> 1 | S7: =SUMPRODUCT(($C$5:$C$34=C7)*($Q$5:$Q$34<Q7)*$AH$5:$AH$34) -> 0 | T7: =INDEX(Funnel!$B$5:$B$8,MATCH(C7,Funnel!$A$5:$A$8,0))-SUMIFS($AG$5:$AG$34,$C$5:$C$34,C7) -> 13.99664 | U7: =AG7+AI7 -> 2.6294625 | V7: =IF(L7>0,U7/L7,0) -> 9.275 | W7: =IF(I7>0,V7/I7,0) -> 53 | X7: =IF(E7="Slot",IF(N(G7)>0,ROUNDUP(W7/G7,0)*MAX(0,F7),0),W7*H7) -> 0 | Y7: =IF(U7>0,Assumptions!J132,0) -> 0 | Z7: =IF(AND(D7="Channel",OR(E7="CPC",E7="CPA"),INDEX(Funnel!$B$5:$B$8,MATCH(C7,Funnel!$A$5:$A$8,0))>0),MIN(Assumptions!$D$49,J7*H7,IF(I7*L7>0,INDEX(Funnel!$B$5:$B$8,MATCH(C7,Funnel!$A$5:$A$8,0))/SUMPRODUCT(($C$5:$C$34=C7)*($D$5:$D$34="Channel")*(($E$5:$E$34="CPC")+($E$5:$E$34="CPA")))/(I7*L7)*H7,0)),0) -> 0 | AA7: =X7+Y7 -> 0 | AB7: =IF(U7>0,(X7+Y7)/U7,"–") -> 0 | AC7: =SUMPRODUCT(--($Q$5:$Q$34<Q7))+1 -> 3 | AD7: =IF(AND(AH7>0,AI7>=AH7*0.999),"Used to capacity",IF(AI7>0,"Marginal (fills the gap)",IF(Z7>0,"Test only (wk 1–2)","Not used"))) -> Used to capacity | AE7: =IF(H7>0,Z7/H7,0) -> 0 | AF7: =AE7*I7 -> 0 | AG7: =AF7*L7 -> 0 | AH7: =MAX(0,N7-AG7) -> 2.6294625 | AI7: =MIN(AH7,MAX(0,T7-S7)) -> 2.6294625
A8: =Assumptions!A133 -> C04 | B8: =Assumptions!B133 -> Organic (Tesla careers, BA Jobbörse, Google for Jobs) | C8: =Assumptions!C133 -> Supervisors | D8: Channel | E8: =Assumptions!D133 -> Free | F8: =Assumptions!E133 -> 0 | G8: =IF(E8="Free","",Assumptions!F133) | H8: =MAX(0,IF(OR(E8="CPC",E8="Slot"),IF(N(G8)>0,F8/G8,0),F8)) -> 0 | I8: =Assumptions!G133 -> 0.161 | J8: =IF(AND(OR(E8="CPC",E8="Slot"),NOT(N(G8)>0)),0,IF(E8="Slot",Assumptions!H133*G8,Assumptions!H133)) -> 35 | K8: =J8*I8 -> 5.635 | L8: =INDEX(Funnel!$G$5:$G$8,MATCH(C8,Funnel!$A$5:$A$8,0))*M8 -> 0.238 | M8: =Assumptions!I133 -> 1 | N8: =K8*L8 -> 1.34113 | O8: =IF(I8>0,H8/I8,0) -> 0 | P8: =IF(N8>0,(N8/L8/I8*H8+Assumptions!J133)/N8,0) -> 0 | Q8: =P8+ROW()/1000000 -> 8e-06 | R8: =SUMPRODUCT(($C$5:$C$34=C8)*($Q$5:$Q$34<Q8))+1 -> 1 | S8: =SUMPRODUCT(($C$5:$C$34=C8)*($Q$5:$Q$34<Q8)*$AH$5:$AH$34) -> 0 | T8: =INDEX(Funnel!$B$5:$B$8,MATCH(C8,Funnel!$A$5:$A$8,0))-SUMIFS($AG$5:$AG$34,$C$5:$C$34,C8) -> 9.2250591 | U8: =AG8+AI8 -> 1.34113 | V8: =IF(L8>0,U8/L8,0) -> 5.635 | W8: =IF(I8>0,V8/I8,0) -> 35 | X8: =IF(E8="Slot",IF(N(G8)>0,ROUNDUP(W8/G8,0)*MAX(0,F8),0),W8*H8) -> 0 | Y8: =IF(U8>0,Assumptions!J133,0) -> 0 | Z8: =IF(AND(D8="Channel",OR(E8="CPC",E8="CPA"),INDEX(Funnel!$B$5:$B$8,MATCH(C8,Funnel!$A$5:$A$8,0))>0),MIN(Assumptions!$D$49,J8*H8,IF(I8*L8>0,INDEX(Funnel!$B$5:$B$8,MATCH(C8,Funnel!$A$5:$A$8,0))/SUMPRODUCT(($C$5:$C$34=C8)*($D$5:$D$34="Channel")*(($E$5:$E$34="CPC")+($E$5:$E$34="CPA")))/(I8*L8)*H8,0)),0) -> 0 | AA8: =X8+Y8 -> 0 | AB8: =IF(U8>0,(X8+Y8)/U8,"–") -> 0 | AC8: =SUMPRODUCT(--($Q$5:$Q$34<Q8))+1 -> 4 | AD8: =IF(AND(AH8>0,AI8>=AH8*0.999),"Used to capacity",IF(AI8>0,"Marginal (fills the gap)",IF(Z8>0,"Test only (wk 1–2)","Not used"))) -> Used to capacity | AE8: =IF(H8>0,Z8/H8,0) -> 0 | AF8: =AE8*I8 -> 0 | AG8: =AF8*L8 -> 0 | AH8: =MAX(0,N8-AG8) -> 1.34113 | AI8: =MIN(AH8,MAX(0,T8-S8)) -> 1.34113
A9: =Assumptions!A134 -> C05 | B9: =Assumptions!B134 -> Programmatic job ads (Joveo: Indeed, Jooble, Talent.com, Kimeta, meinestadt…) | C9: =Assumptions!C134 -> Electricians | D9: Channel | E9: =Assumptions!D134 -> CPA | F9: =Assumptions!E134 -> 161 | G9: =IF(E9="Free","",Assumptions!F134) -> 0 | H9: =MAX(0,IF(OR(E9="CPC",E9="Slot"),IF(N(G9)>0,F9/G9,0),F9)) -> 161 | I9: =Assumptions!G134 -> 0.225 | J9: =IF(AND(OR(E9="CPC",E9="Slot"),NOT(N(G9)>0)),0,IF(E9="Slot",Assumptions!H134*G9,Assumptions!H134)) -> 910 | K9: =J9*I9 -> 204.75 | L9: =INDEX(Funnel!$G$5:$G$8,MATCH(C9,Funnel!$A$5:$A$8,0))*M9 -> 0.315 | M9: =Assumptions!I134 -> 1 | N9: =K9*L9 -> 64.49625 | O9: =IF(I9>0,H9/I9,0) -> 715.55556 | P9: =IF(N9>0,(N9/L9/I9*H9+Assumptions!J134)/N9,0) -> 2271.6049 | Q9: =P9+ROW()/1000000 -> 2271.6049 | R9: =SUMPRODUCT(($C$5:$C$34=C9)*($Q$5:$Q$34<Q9))+1 -> 6 | S9: =SUMPRODUCT(($C$5:$C$34=C9)*($Q$5:$Q$34<Q9)*$AH$5:$AH$34) -> 20.5254 | T9: =INDEX(Funnel!$B$5:$B$8,MATCH(C9,Funnel!$A$5:$A$8,0))-SUMIFS($AG$5:$AG$34,$C$5:$C$34,C9) -> 29.150585 | U9: =AG9+AI9 -> 8.9553481 | V9: =IF(L9>0,U9/L9,0) -> 28.429676 | W9: =IF(I9>0,V9/I9,0) -> 126.35412 | X9: =IF(E9="Slot",IF(N(G9)>0,ROUNDUP(W9/G9,0)*MAX(0,F9),0),W9*H9) -> 20343.013 | Y9: =IF(U9>0,Assumptions!J134,0) -> 0 | Z9: =IF(AND(D9="Channel",OR(E9="CPC",E9="CPA"),INDEX(Funnel!$B$5:$B$8,MATCH(C9,Funnel!$A$5:$A$8,0))>0),MIN(Assumptions!$D$49,J9*H9,IF(I9*L9>0,INDEX(Funnel!$B$5:$B$8,MATCH(C9,Funnel!$A$5:$A$8,0))/SUMPRODUCT(($C$5:$C$34=C9)*($D$5:$D$34="Channel")*(($E$5:$E$34="CPC")+($E$5:$E$34="CPA")))/(I9*L9)*H9,0)),0) -> 750 | AA9: =X9+Y9 -> 20343.013 | AB9: =IF(U9>0,(X9+Y9)/U9,"–") -> 2271.6049 | AC9: =SUMPRODUCT(--($Q$5:$Q$34<Q9))+1 -> 22 | AD9: =IF(AND(AH9>0,AI9>=AH9*0.999),"Used to capacity",IF(AI9>0,"Marginal (fills the gap)",IF(Z9>0,"Test only (wk 1–2)","Not used"))) -> Marginal (fills the gap) | AE9: =IF(H9>0,Z9/H9,0) -> 4.6583851 | AF9: =AE9*I9 -> 1.0481366 | AG9: =AF9*L9 -> 0.33016304 | AH9: =MAX(0,N9-AG9) -> 64.166087 | AI9: =MIN(AH9,MAX(0,T9-S9)) -> 8.625185
A10: =Assumptions!A135 -> C06 | B10: =Assumptions!B135 -> Programmatic job ads (Joveo: Indeed, Jooble, Talent.com, Kimeta, meinestadt…) | C10: =Assumptions!C135 -> Mechatronics | D10: Channel | E10: =Assumptions!D135 -> CPA | F10: =Assumptions!E135 -> 161 | G10: =IF(E10="Free","",Assumptions!F135) -> 0 | H10: =MAX(0,IF(OR(E10="CPC",E10="Slot"),IF(N(G10)>0,F10/G10,0),F10)) -> 161 | I10: =Assumptions!G135 -> 0.225 | J10: =IF(AND(OR(E10="CPC",E10="Slot"),NOT(N(G10)>0)),0,IF(E10="Slot",Assumptions!H135*G10,Assumptions!H135)) -> 4690 | K10: =J10*I10 -> 1055.25 | L10: =INDEX(Funnel!$G$5:$G$8,MATCH(C10,Funnel!$A$5:$A$8,0))*M10 -> 0.37125 | M10: =Assumptions!I135 -> 1 | N10: =K10*L10 -> 391.76156 | O10: =IF(I10>0,H10/I10,0) -> 715.55556 | P10: =IF(N10>0,(N10/L10/I10*H10+Assumptions!J135)/N10,0) -> 1927.4224 | Q10: =P10+ROW()/1000000 -> 1927.4224 | R10: =SUMPRODUCT(($C$5:$C$34=C10)*($Q$5:$Q$34<Q10))+1 -> 6 | S10: =SUMPRODUCT(($C$5:$C$34=C10)*($Q$5:$Q$34<Q10)*$AH$5:$AH$34) -> 37.211816 | T10: =INDEX(Funnel!$B$5:$B$8,MATCH(C10,Funnel!$A$5:$A$8,0))-SUMIFS($AG$5:$AG$34,$C$5:$C$34,C10) -> 43.998904 | U10: =AG10+AI10 -> 7.1762083 | V10: =IF(L10>0,U10/L10,0) -> 19.329854 | W10: =IF(I10>0,V10/I10,0) -> 85.910462 | X10: =IF(E10="Slot",IF(N(G10)>0,ROUNDUP(W10/G10,0)*MAX(0,F10),0),W10*H10) -> 13831.584 | Y10: =IF(U10>0,Assumptions!J135,0) -> 0 | Z10: =IF(AND(D10="Channel",OR(E10="CPC",E10="CPA"),INDEX(Funnel!$B$5:$B$8,MATCH(C10,Funnel!$A$5:$A$8,0))>0),MIN(Assumptions!$D$49,J10*H10,IF(I10*L10>0,INDEX(Funnel!$B$5:$B$8,MATCH(C10,Funnel!$A$5:$A$8,0))/SUMPRODUCT(($C$5:$C$34=C10)*($D$5:$D$34="Channel")*(($E$5:$E$34="CPC")+($E$5:$E$34="CPA")))/(I10*L10)*H10,0)),0) -> 750 | AA10: =X10+Y10 -> 13831.584 | AB10: =IF(U10>0,(X10+Y10)/U10,"–") -> 1927.4224 | AC10: =SUMPRODUCT(--($Q$5:$Q$34<Q10))+1 -> 19 | AD10: =IF(AND(AH10>0,AI10>=AH10*0.999),"Used to capacity",IF(AI10>0,"Marginal (fills the gap)",IF(Z10>0,"Test only (wk 1–2)","Not used"))) -> Marginal (fills the gap) | AE10: =IF(H10>0,Z10/H10,0) -> 4.6583851 | AF10: =AE10*I10 -> 1.0481366 | AG10: =AF10*L10 -> 0.38912073 | AH10: =MAX(0,N10-AG10) -> 391.37244 | AI10: =MIN(AH10,MAX(0,T10-S10)) -> 6.7870875
A11: =Assumptions!A136 -> C07 | B11: =Assumptions!B136 -> Programmatic job ads (Joveo: Indeed, Jooble, Talent.com, Kimeta, meinestadt…) | C11: =Assumptions!C136 -> Automation | D11: Channel | E11: =Assumptions!D136 -> CPA | F11: =Assumptions!E136 -> 161 | G11: =IF(E11="Free","",Assumptions!F136) -> 0 | H11: =MAX(0,IF(OR(E11="CPC",E11="Slot"),IF(N(G11)>0,F11/G11,0),F11)) -> 161 | I11: =Assumptions!G136 -> 0.225 | J11: =IF(AND(OR(E11="CPC",E11="Slot"),NOT(N(G11)>0)),0,IF(E11="Slot",Assumptions!H136*G11,Assumptions!H136)) -> 380 | K11: =J11*I11 -> 85.5 | L11: =INDEX(Funnel!$G$5:$G$8,MATCH(C11,Funnel!$A$5:$A$8,0))*M11 -> 0.2835 | M11: =Assumptions!I136 -> 1 | N11: =K11*L11 -> 24.23925 | O11: =IF(I11>0,H11/I11,0) -> 715.55556 | P11: =IF(N11>0,(N11/L11/I11*H11+Assumptions!J136)/N11,0) -> 2524.0055 | Q11: =P11+ROW()/1000000 -> 2524.0055 | R11: =SUMPRODUCT(($C$5:$C$34=C11)*($Q$5:$Q$34<Q11))+1 -> 6 | S11: =SUMPRODUCT(($C$5:$C$34=C11)*($Q$5:$Q$34<Q11)*$AH$5:$AH$34) -> 16.225183 | T11: =INDEX(Funnel!$B$5:$B$8,MATCH(C11,Funnel!$A$5:$A$8,0))-SUMIFS($AG$5:$AG$34,$C$5:$C$34,C11) -> 13.99664 | U11: =AG11+AI11 -> 0.29714674 | V11: =IF(L11>0,U11/L11,0) -> 1.0481366 | W11: =IF(I11>0,V11/I11,0) -> 4.6583851 | X11: =IF(E11="Slot",IF(N(G11)>0,ROUNDUP(W11/G11,0)*MAX(0,F11),0),W11*H11) -> 750 | Y11: =IF(U11>0,Assumptions!J136,0) -> 0 | Z11: =IF(AND(D11="Channel",OR(E11="CPC",E11="CPA"),INDEX(Funnel!$B$5:$B$8,MATCH(C11,Funnel!$A$5:$A$8,0))>0),MIN(Assumptions!$D$49,J11*H11,IF(I11*L11>0,INDEX(Funnel!$B$5:$B$8,MATCH(C11,Funnel!$A$5:$A$8,0))/SUMPRODUCT(($C$5:$C$34=C11)*($D$5:$D$34="Channel")*(($E$5:$E$34="CPC")+($E$5:$E$34="CPA")))/(I11*L11)*H11,0)),0) -> 750 | AA11: =X11+Y11 -> 750 | AB11: =IF(U11>0,(X11+Y11)/U11,"–") -> 2524.0055 | AC11: =SUMPRODUCT(--($Q$5:$Q$34<Q11))+1 -> 24 | AD11: =IF(AND(AH11>0,AI11>=AH11*0.999),"Used to capacity",IF(AI11>0,"Marginal (fills the gap)",IF(Z11>0,"Test only (wk 1–2)","Not used"))) -> Test only (wk 1–2) | AE11: =IF(H11>0,Z11/H11,0) -> 4.6583851 | AF11: =AE11*I11 -> 1.0481366 | AG11: =AF11*L11 -> 0.29714674 | AH11: =MAX(0,N11-AG11) -> 23.942103 | AI11: =MIN(AH11,MAX(0,T11-S11)) -> 0
A12: =Assumptions!A137 -> C08 | B12: =Assumptions!B137 -> Programmatic job ads (Joveo: Indeed, Jooble, Talent.com, Kimeta, meinestadt…) | C12: =Assumptions!C137 -> Supervisors | D12: Channel | E12: =Assumptions!D137 -> CPA | F12: =Assumptions!E137 -> 161 | G12: =IF(E12="Free","",Assumptions!F137) -> 0 | H12: =MAX(0,IF(OR(E12="CPC",E12="Slot"),IF(N(G12)>0,F12/G12,0),F12)) -> 161 | I12: =Assumptions!G137 -> 0.207 | J12: =IF(AND(OR(E12="CPC",E12="Slot"),NOT(N(G12)>0)),0,IF(E12="Slot",Assumptions!H137*G12,Assumptions!H137)) -> 430 | K12: =J12*I12 -> 89.01 | L12: =INDEX(Funnel!$G$5:$G$8,MATCH(C12,Funnel!$A$5:$A$8,0))*M12 -> 0.238 | M12: =Assumptions!I137 -> 1 | N12: =K12*L12 -> 21.18438 | O12: =IF(I12>0,H12/I12,0) -> 777.77778 | P12: =IF(N12>0,(N12/L12/I12*H12+Assumptions!J137)/N12,0) -> 3267.9739 | Q12: =P12+ROW()/1000000 -> 3267.9739 | R12: =SUMPRODUCT(($C$5:$C$34=C12)*($Q$5:$Q$34<Q12))+1 -> 6 | S12: =SUMPRODUCT(($C$5:$C$34=C12)*($Q$5:$Q$34<Q12)*$AH$5:$AH$34) -> 12.0493 | T12: =INDEX(Funnel!$B$5:$B$8,MATCH(C12,Funnel!$A$5:$A$8,0))-SUMIFS($AG$5:$AG$34,$C$5:$C$34,C12) -> 9.2250591 | U12: =AG12+AI12 -> 0.2295 | V12: =IF(L12>0,U12/L12,0) -> 0.96428571 | W12: =IF(I12>0,V12/I12,0) -> 4.6583851 | X12: =IF(E12="Slot",IF(N(G12)>0,ROUNDUP(W12/G12,0)*MAX(0,F12),0),W12*H12) -> 750 | Y12: =IF(U12>0,Assumptions!J137,0) -> 0 | Z12: =IF(AND(D12="Channel",OR(E12="CPC",E12="CPA"),INDEX(Funnel!$B$5:$B$8,MATCH(C12,Funnel!$A$5:$A$8,0))>0),MIN(Assumptions!$D$49,J12*H12,IF(I12*L12>0,INDEX(Funnel!$B$5:$B$8,MATCH(C12,Funnel!$A$5:$A$8,0))/SUMPRODUCT(($C$5:$C$34=C12)*($D$5:$D$34="Channel")*(($E$5:$E$34="CPC")+($E$5:$E$34="CPA")))/(I12*L12)*H12,0)),0) -> 750 | AA12: =X12+Y12 -> 750 | AB12: =IF(U12>0,(X12+Y12)/U12,"–") -> 3267.9739 | AC12: =SUMPRODUCT(--($Q$5:$Q$34<Q12))+1 -> 28 | AD12: =IF(AND(AH12>0,AI12>=AH12*0.999),"Used to capacity",IF(AI12>0,"Marginal (fills the gap)",IF(Z12>0,"Test only (wk 1–2)","Not used"))) -> Test only (wk 1–2) | AE12: =IF(H12>0,Z12/H12,0) -> 4.6583851 | AF12: =AE12*I12 -> 0.96428571 | AG12: =AF12*L12 -> 0.2295 | AH12: =MAX(0,N12-AG12) -> 20.95488 | AI12: =MIN(AH12,MAX(0,T12-S12)) -> 0
A13: =Assumptions!A138 -> C09 | B13: =Assumptions!B138 -> StepStone (30-day single ad) | C13: =Assumptions!C138 -> Electricians | D13: Channel | E13: =Assumptions!D138 -> Slot | F13: =Assumptions!E138 -> 1449 | G13: =IF(E13="Free","",Assumptions!F138) -> 12 | H13: =MAX(0,IF(OR(E13="CPC",E13="Slot"),IF(N(G13)>0,F13/G13,0),F13)) -> 120.75 | I13: =Assumptions!G138 -> 0.225 | J13: =IF(AND(OR(E13="CPC",E13="Slot"),NOT(N(G13)>0)),0,IF(E13="Slot",Assumptions!H138*G13,Assumptions!H138)) -> 24 | K13: =J13*I13 -> 5.4 | L13: =INDEX(Funnel!$G$5:$G$8,MATCH(C13,Funnel!$A$5:$A$8,0))*M13 -> 0.315 | M13: =Assumptions!I138 -> 1 | N13: =K13*L13 -> 1.701 | O13: =IF(I13>0,H13/I13,0) -> 536.66667 | P13: =IF(N13>0,(N13/L13/I13*H13+Assumptions!J138)/N13,0) -> 1703.7037 | Q13: =P13+ROW()/1000000 -> 1703.7037 | R13: =SUMPRODUCT(($C$5:$C$34=C13)*($Q$5:$Q$34<Q13))+1 -> 5 | S13: =SUMPRODUCT(($C$5:$C$34=C13)*($Q$5:$Q$34<Q13)*$AH$5:$AH$34) -> 18.8244 | T13: =INDEX(Funnel!$B$5:$B$8,MATCH(C13,Funnel!$A$5:$A$8,0))-SUMIFS($AG$5:$AG$34,$C$5:$C$34,C13) -> 29.150585 | U13: =AG13+AI13 -> 1.701 | V13: =IF(L13>0,U13/L13,0) -> 5.4 | W13: =IF(I13>0,V13/I13,0) -> 24 | X13: =IF(E13="Slot",IF(N(G13)>0,ROUNDUP(W13/G13,0)*MAX(0,F13),0),W13*H13) -> 2898 | Y13: =IF(U13>0,Assumptions!J138,0) -> 0 | Z13: =IF(AND(D13="Channel",OR(E13="CPC",E13="CPA"),INDEX(Funnel!$B$5:$B$8,MATCH(C13,Funnel!$A$5:$A$8,0))>0),MIN(Assumptions!$D$49,J13*H13,IF(I13*L13>0,INDEX(Funnel!$B$5:$B$8,MATCH(C13,Funnel!$A$5:$A$8,0))/SUMPRODUCT(($C$5:$C$34=C13)*($D$5:$D$34="Channel")*(($E$5:$E$34="CPC")+($E$5:$E$34="CPA")))/(I13*L13)*H13,0)),0) -> 0 | AA13: =X13+Y13 -> 2898 | AB13: =IF(U13>0,(X13+Y13)/U13,"–") -> 1703.7037 | AC13: =SUMPRODUCT(--($Q$5:$Q$34<Q13))+1 -> 17 | AD13: =IF(AND(AH13>0,AI13>=AH13*0.999),"Used to capacity",IF(AI13>0,"Marginal (fills the gap)",IF(Z13>0,"Test only (wk 1–2)","Not used"))) -> Used to capacity | AE13: =IF(H13>0,Z13/H13,0) -> 0 | AF13: =AE13*I13 -> 0 | AG13: =AF13*L13 -> 0 | AH13: =MAX(0,N13-AG13) -> 1.701 | AI13: =MIN(AH13,MAX(0,T13-S13)) -> 1.701
